ERROR:root:
Mon Oct 15 21:57:19 2018
Traceback (most recent call last):
  File "/home/dj/.pling/dg-prosjekt/pling-project/main.py", line 65, in <module>
  File "/home/dj/.pling/dg-prosjekt/pling-project/main.py", line 50, in main
  File "/home/dj/.pling/dg-prosjekt/pling-project/plingMeny.py", line 214, in run
  File "/usr/lib/python2.7/lib-tk/Tkinter.py", line 1133, in mainloop
    self.tk.mainloop(n)
  File "/home/dj/.pling/dg-prosjekt/pling-project/plingMeny.py", line 234, in __call__
  File "/home/dj/.pling/dg-prosjekt/pling-project/plingMeny.py", line 105, in on_closing
  File "/home/dj/.pling/dg-prosjekt/pling-project/plingMeny.py", line 123, in killGUI
IOError: [Errno 2] No such file or directory: '/home/dj/.pling/dg-prosjekt/pling-project/plingMeta.csv'
ERROR:root:
02/20/20 20:50:05
Traceback (most recent call last):
  File "c:/Users/g-oft/OneDrive/Dokumenter/DG/dg-prosjekt/pling-project/main.py", line 65, in <module>
    main()
  File "c:/Users/g-oft/OneDrive/Dokumenter/DG/dg-prosjekt/pling-project/main.py", line 46, in main
    meny = plingMeny(verbose=VERBOSE)
  File "c:\Users\g-oft\OneDrive\Dokumenter\DG\dg-prosjekt\pling-project\plingMeny.py", line 30, in __init__
    icon = Tkinter.PhotoImage(file=os.path.join(self.script_dir,'files/icon.png'))
  File "C:\Python27\lib\lib-tk\Tkinter.py", line 3366, in __init__
    Image.__init__(self, 'photo', name, cnf, master, **kw)
  File "C:\Python27\lib\lib-tk\Tkinter.py", line 3320, in __init__
    self.tk.call(('image', 'create', imgtype, name,) + options)
TclError: couldn't recognize data in image file "c:\Users\g-oft\OneDrive\Dokumenter\DG\dg-prosjekt\pling-project\files/icon.png"
ERROR:root:
02/20/20 20:51:48
Traceback (most recent call last):
  File "c:/Users/g-oft/OneDrive/Dokumenter/DG/dg-prosjekt/pling-project/main.py", line 65, in <module>
    main()
  File "c:/Users/g-oft/OneDrive/Dokumenter/DG/dg-prosjekt/pling-project/main.py", line 46, in main
    meny = plingMeny(verbose=VERBOSE)
  File "c:\Users\g-oft\OneDrive\Dokumenter\DG\dg-prosjekt\pling-project\plingMeny.py", line 30, in __init__
    icon = Tkinter.PhotoImage(file=os.path.join(self.script_dir,'files/icon.png'))
  File "C:\Python27\lib\lib-tk\Tkinter.py", line 3366, in __init__
    Image.__init__(self, 'photo', name, cnf, master, **kw)
  File "C:\Python27\lib\lib-tk\Tkinter.py", line 3320, in __init__
    self.tk.call(('image', 'create', imgtype, name,) + options)
TclError: couldn't recognize data in image file "c:\Users\g-oft\OneDrive\Dokumenter\DG\dg-prosjekt\pling-project\files/icon.png"
ERROR:root:
02/20/20 20:53:42
Traceback (most recent call last):
  File "c:/Users/g-oft/OneDrive/Dokumenter/DG/dg-prosjekt/pling-project/main.py", line 66, in <module>
    main()
  File "c:/Users/g-oft/OneDrive/Dokumenter/DG/dg-prosjekt/pling-project/main.py", line 46, in main
    meny = plingMeny(verbose=VERBOSE)
  File "c:\Users\g-oft\OneDrive\Dokumenter\DG\dg-prosjekt\pling-project\plingMeny.py", line 30, in __init__
    icon = Tkinter.PhotoImage(file=os.path.join(self.script_dir,'files/icon.png'))
  File "C:\Python27\lib\lib-tk\Tkinter.py", line 3366, in __init__
    Image.__init__(self, 'photo', name, cnf, master, **kw)
  File "C:\Python27\lib\lib-tk\Tkinter.py", line 3320, in __init__
    self.tk.call(('image', 'create', imgtype, name,) + options)
TclError: couldn't recognize data in image file "c:\Users\g-oft\OneDrive\Dokumenter\DG\dg-prosjekt\pling-project\files/icon.png"
ERROR:root:
02/20/20 20:55:04
Traceback (most recent call last):
  File "c:/Users/g-oft/OneDrive/Dokumenter/DG/dg-prosjekt/pling-project/main.py", line 66, in <module>
    main()
  File "c:/Users/g-oft/OneDrive/Dokumenter/DG/dg-prosjekt/pling-project/main.py", line 46, in main
    meny = plingMeny(verbose=VERBOSE)
  File "c:\Users\g-oft\OneDrive\Dokumenter\DG\dg-prosjekt\pling-project\plingMeny.py", line 30, in __init__
    icon = Tkinter.PhotoImage(file=os.path.join(self.script_dir,'files/icon.png'))
  File "C:\Python27\lib\lib-tk\Tkinter.py", line 3366, in __init__
    Image.__init__(self, 'photo', name, cnf, master, **kw)
  File "C:\Python27\lib\lib-tk\Tkinter.py", line 3320, in __init__
    self.tk.call(('image', 'create', imgtype, name,) + options)
TclError: couldn't recognize data in image file "c:\Users\g-oft\OneDrive\Dokumenter\DG\dg-prosjekt\pling-project\files/icon.png"
ERROR:root:
02/20/20 20:55:22
Traceback (most recent call last):
  File "c:/Users/g-oft/OneDrive/Dokumenter/DG/dg-prosjekt/pling-project/main.py", line 67, in <module>
    main()
  File "c:/Users/g-oft/OneDrive/Dokumenter/DG/dg-prosjekt/pling-project/main.py", line 46, in main
    meny = plingMeny(verbose=VERBOSE)
  File "c:\Users\g-oft\OneDrive\Dokumenter\DG\dg-prosjekt\pling-project\plingMeny.py", line 30, in __init__
    icon = Tkinter.PhotoImage(file=os.path.join(self.script_dir,'files/icon.png'))
  File "C:\Python27\lib\lib-tk\Tkinter.py", line 3366, in __init__
    Image.__init__(self, 'photo', name, cnf, master, **kw)
  File "C:\Python27\lib\lib-tk\Tkinter.py", line 3320, in __init__
    self.tk.call(('image', 'create', imgtype, name,) + options)
TclError: couldn't recognize data in image file "c:\Users\g-oft\OneDrive\Dokumenter\DG\dg-prosjekt\pling-project\files/icon.png"
ERROR:root:
02/20/20 20:55:39
Traceback (most recent call last):
  File "c:/Users/g-oft/OneDrive/Dokumenter/DG/dg-prosjekt/pling-project/main.py", line 67, in <module>
    main()
  File "c:/Users/g-oft/OneDrive/Dokumenter/DG/dg-prosjekt/pling-project/main.py", line 46, in main
    meny = plingMeny(verbose=VERBOSE)
  File "c:\Users\g-oft\OneDrive\Dokumenter\DG\dg-prosjekt\pling-project\plingMeny.py", line 30, in __init__
    icon = Tkinter.PhotoImage(file=os.path.join(self.script_dir,'files/icon.png'))
  File "C:\Python27\lib\lib-tk\Tkinter.py", line 3366, in __init__
    Image.__init__(self, 'photo', name, cnf, master, **kw)
  File "C:\Python27\lib\lib-tk\Tkinter.py", line 3320, in __init__
    self.tk.call(('image', 'create', imgtype, name,) + options)
TclError: couldn't recognize data in image file "c:\Users\g-oft\OneDrive\Dokumenter\DG\dg-prosjekt\pling-project\files/icon.png"
ERROR:root:
02/20/20 20:55:48
Traceback (most recent call last):
  File "c:/Users/g-oft/OneDrive/Dokumenter/DG/dg-prosjekt/pling-project/main.py", line 68, in <module>
    main()
  File "c:/Users/g-oft/OneDrive/Dokumenter/DG/dg-prosjekt/pling-project/main.py", line 47, in main
    meny = plingMeny(verbose=VERBOSE)
  File "c:\Users\g-oft\OneDrive\Dokumenter\DG\dg-prosjekt\pling-project\plingMeny.py", line 30, in __init__
    icon = Tkinter.PhotoImage(file=os.path.join(self.script_dir,'files/icon.png'))
  File "C:\Python27\lib\lib-tk\Tkinter.py", line 3366, in __init__
    Image.__init__(self, 'photo', name, cnf, master, **kw)
  File "C:\Python27\lib\lib-tk\Tkinter.py", line 3320, in __init__
    self.tk.call(('image', 'create', imgtype, name,) + options)
TclError: couldn't recognize data in image file "c:\Users\g-oft\OneDrive\Dokumenter\DG\dg-prosjekt\pling-project\files/icon.png"
ERROR:root:
02/20/20 20:55:56
Traceback (most recent call last):
  File "c:/Users/g-oft/OneDrive/Dokumenter/DG/dg-prosjekt/pling-project/main.py", line 69, in <module>
    main()
  File "c:/Users/g-oft/OneDrive/Dokumenter/DG/dg-prosjekt/pling-project/main.py", line 47, in main
    meny = plingMeny(verbose=VERBOSE)
  File "c:\Users\g-oft\OneDrive\Dokumenter\DG\dg-prosjekt\pling-project\plingMeny.py", line 30, in __init__
    icon = Tkinter.PhotoImage(file=os.path.join(self.script_dir,'files/icon.png'))
  File "C:\Python27\lib\lib-tk\Tkinter.py", line 3366, in __init__
    Image.__init__(self, 'photo', name, cnf, master, **kw)
  File "C:\Python27\lib\lib-tk\Tkinter.py", line 3320, in __init__
    self.tk.call(('image', 'create', imgtype, name,) + options)
TclError: couldn't recognize data in image file "c:\Users\g-oft\OneDrive\Dokumenter\DG\dg-prosjekt\pling-project\files/icon.png"
ERROR:root:
02/20/20 20:56:09
Traceback (most recent call last):
  File "c:/Users/g-oft/OneDrive/Dokumenter/DG/dg-prosjekt/pling-project/main.py", line 70, in <module>
    main()
  File "c:/Users/g-oft/OneDrive/Dokumenter/DG/dg-prosjekt/pling-project/main.py", line 48, in main
    meny = plingMeny(verbose=VERBOSE)
  File "c:\Users\g-oft\OneDrive\Dokumenter\DG\dg-prosjekt\pling-project\plingMeny.py", line 30, in __init__
    icon = Tkinter.PhotoImage(file=os.path.join(self.script_dir,'files/icon.png'))
  File "C:\Python27\lib\lib-tk\Tkinter.py", line 3366, in __init__
    Image.__init__(self, 'photo', name, cnf, master, **kw)
  File "C:\Python27\lib\lib-tk\Tkinter.py", line 3320, in __init__
    self.tk.call(('image', 'create', imgtype, name,) + options)
TclError: couldn't recognize data in image file "c:\Users\g-oft\OneDrive\Dokumenter\DG\dg-prosjekt\pling-project\files/icon.png"
ERROR:root:
02/20/20 20:56:18
Traceback (most recent call last):
  File "c:/Users/g-oft/OneDrive/Dokumenter/DG/dg-prosjekt/pling-project/main.py", line 71, in <module>
    main()
  File "c:/Users/g-oft/OneDrive/Dokumenter/DG/dg-prosjekt/pling-project/main.py", line 48, in main
    meny = plingMeny(verbose=VERBOSE)
  File "c:\Users\g-oft\OneDrive\Dokumenter\DG\dg-prosjekt\pling-project\plingMeny.py", line 30, in __init__
    icon = Tkinter.PhotoImage(file=os.path.join(self.script_dir,'files/icon.png'))
  File "C:\Python27\lib\lib-tk\Tkinter.py", line 3366, in __init__
    Image.__init__(self, 'photo', name, cnf, master, **kw)
  File "C:\Python27\lib\lib-tk\Tkinter.py", line 3320, in __init__
    self.tk.call(('image', 'create', imgtype, name,) + options)
TclError: couldn't recognize data in image file "c:\Users\g-oft\OneDrive\Dokumenter\DG\dg-prosjekt\pling-project\files/icon.png"
ERROR:root:
02/20/20 20:56:55
Traceback (most recent call last):
  File "c:/Users/g-oft/OneDrive/Dokumenter/DG/dg-prosjekt/pling-project/main.py", line 63, in <module>
    main()
  File "c:/Users/g-oft/OneDrive/Dokumenter/DG/dg-prosjekt/pling-project/main.py", line 44, in main
    meny = plingMeny(verbose=VERBOSE)
  File "c:\Users\g-oft\OneDrive\Dokumenter\DG\dg-prosjekt\pling-project\plingMeny.py", line 30, in __init__
    icon = Tkinter.PhotoImage(file=os.path.join(self.script_dir,'files/icon.png'))
  File "C:\Python27\lib\lib-tk\Tkinter.py", line 3366, in __init__
    Image.__init__(self, 'photo', name, cnf, master, **kw)
  File "C:\Python27\lib\lib-tk\Tkinter.py", line 3320, in __init__
    self.tk.call(('image', 'create', imgtype, name,) + options)
TclError: couldn't recognize data in image file "c:\Users\g-oft\OneDrive\Dokumenter\DG\dg-prosjekt\pling-project\files/icon.png"
ERROR:root:
02/20/20 20:57:36
Traceback (most recent call last):
  File "c:/Users/g-oft/OneDrive/Dokumenter/DG/dg-prosjekt/pling-project/main.py", line 64, in <module>
    main()
  File "c:/Users/g-oft/OneDrive/Dokumenter/DG/dg-prosjekt/pling-project/main.py", line 44, in main
    meny = plingMeny(verbose=VERBOSE)
  File "c:\Users\g-oft\OneDrive\Dokumenter\DG\dg-prosjekt\pling-project\plingMeny.py", line 30, in __init__
    icon = Tkinter.PhotoImage(file=os.path.join(self.script_dir,'files/icon.png'))
  File "C:\Python27\lib\lib-tk\Tkinter.py", line 3366, in __init__
    Image.__init__(self, 'photo', name, cnf, master, **kw)
  File "C:\Python27\lib\lib-tk\Tkinter.py", line 3320, in __init__
    self.tk.call(('image', 'create', imgtype, name,) + options)
TclError: couldn't recognize data in image file "c:\Users\g-oft\OneDrive\Dokumenter\DG\dg-prosjekt\pling-project\files/icon.png"
ERROR:root:
02/20/20 20:58:11
Traceback (most recent call last):
  File "c:/Users/g-oft/OneDrive/Dokumenter/DG/dg-prosjekt/pling-project/main.py", line 63, in <module>
    main()
  File "c:/Users/g-oft/OneDrive/Dokumenter/DG/dg-prosjekt/pling-project/main.py", line 44, in main
    meny = plingMeny(verbose=VERBOSE)
  File "c:\Users\g-oft\OneDrive\Dokumenter\DG\dg-prosjekt\pling-project\plingMeny.py", line 30, in __init__
    icon = Tkinter.PhotoImage(file=os.path.join(self.script_dir,'files/icon.png'))
  File "C:\Python27\lib\lib-tk\Tkinter.py", line 3366, in __init__
    Image.__init__(self, 'photo', name, cnf, master, **kw)
  File "C:\Python27\lib\lib-tk\Tkinter.py", line 3320, in __init__
    self.tk.call(('image', 'create', imgtype, name,) + options)
TclError: couldn't recognize data in image file "c:\Users\g-oft\OneDrive\Dokumenter\DG\dg-prosjekt\pling-project\files/icon.png"
ERROR:root:
02/20/20 20:58:19
Traceback (most recent call last):
  File "c:/Users/g-oft/OneDrive/Dokumenter/DG/dg-prosjekt/pling-project/main.py", line 63, in <module>
    main()
  File "c:/Users/g-oft/OneDrive/Dokumenter/DG/dg-prosjekt/pling-project/main.py", line 44, in main
    meny = plingMeny(verbose=VERBOSE)
  File "c:\Users\g-oft\OneDrive\Dokumenter\DG\dg-prosjekt\pling-project\plingMeny.py", line 30, in __init__
    icon = Tkinter.PhotoImage(file=os.path.join(self.script_dir,'files/icon.png'))
  File "C:\Python27\lib\lib-tk\Tkinter.py", line 3366, in __init__
    Image.__init__(self, 'photo', name, cnf, master, **kw)
  File "C:\Python27\lib\lib-tk\Tkinter.py", line 3320, in __init__
    self.tk.call(('image', 'create', imgtype, name,) + options)
TclError: couldn't recognize data in image file "c:\Users\g-oft\OneDrive\Dokumenter\DG\dg-prosjekt\pling-project\files/icon.png"
ERROR:root:
02/20/20 20:58:28
Traceback (most recent call last):
  File "c:/Users/g-oft/OneDrive/Dokumenter/DG/dg-prosjekt/pling-project/main.py", line 63, in <module>
    main()
  File "c:/Users/g-oft/OneDrive/Dokumenter/DG/dg-prosjekt/pling-project/main.py", line 44, in main
    meny = plingMeny(verbose=VERBOSE)
  File "c:\Users\g-oft\OneDrive\Dokumenter\DG\dg-prosjekt\pling-project\plingMeny.py", line 30, in __init__
    icon = Tkinter.PhotoImage(file=os.path.join(self.script_dir,'files/icon.png'))
  File "C:\Python27\lib\lib-tk\Tkinter.py", line 3366, in __init__
    Image.__init__(self, 'photo', name, cnf, master, **kw)
  File "C:\Python27\lib\lib-tk\Tkinter.py", line 3320, in __init__
    self.tk.call(('image', 'create', imgtype, name,) + options)
TclError: couldn't recognize data in image file "c:\Users\g-oft\OneDrive\Dokumenter\DG\dg-prosjekt\pling-project\files/icon.png"
ERROR:root:
02/20/20 20:58:46
Traceback (most recent call last):
  File "c:/Users/g-oft/OneDrive/Dokumenter/DG/dg-prosjekt/pling-project/main.py", line 64, in <module>
    main()
  File "c:/Users/g-oft/OneDrive/Dokumenter/DG/dg-prosjekt/pling-project/main.py", line 45, in main
    meny = plingMeny(verbose=VERBOSE)
  File "c:\Users\g-oft\OneDrive\Dokumenter\DG\dg-prosjekt\pling-project\plingMeny.py", line 30, in __init__
    icon = Tkinter.PhotoImage(file=os.path.join(self.script_dir,'files/icon.png'))
  File "C:\Python27\lib\lib-tk\Tkinter.py", line 3366, in __init__
    Image.__init__(self, 'photo', name, cnf, master, **kw)
  File "C:\Python27\lib\lib-tk\Tkinter.py", line 3320, in __init__
    self.tk.call(('image', 'create', imgtype, name,) + options)
TclError: couldn't recognize data in image file "c:\Users\g-oft\OneDrive\Dokumenter\DG\dg-prosjekt\pling-project\files/icon.png"
ERROR:root:
02/20/20 20:58:57
Traceback (most recent call last):
  File "c:/Users/g-oft/OneDrive/Dokumenter/DG/dg-prosjekt/pling-project/main.py", line 65, in <module>
    main()
  File "c:/Users/g-oft/OneDrive/Dokumenter/DG/dg-prosjekt/pling-project/main.py", line 46, in main
    meny = plingMeny(verbose=VERBOSE)
  File "c:\Users\g-oft\OneDrive\Dokumenter\DG\dg-prosjekt\pling-project\plingMeny.py", line 30, in __init__
    icon = Tkinter.PhotoImage(file=os.path.join(self.script_dir,'files/icon.png'))
  File "C:\Python27\lib\lib-tk\Tkinter.py", line 3366, in __init__
    Image.__init__(self, 'photo', name, cnf, master, **kw)
  File "C:\Python27\lib\lib-tk\Tkinter.py", line 3320, in __init__
    self.tk.call(('image', 'create', imgtype, name,) + options)
TclError: couldn't recognize data in image file "c:\Users\g-oft\OneDrive\Dokumenter\DG\dg-prosjekt\pling-project\files/icon.png"
ERROR:root:
02/20/20 20:59:01
Traceback (most recent call last):
  File "c:/Users/g-oft/OneDrive/Dokumenter/DG/dg-prosjekt/pling-project/main.py", line 65, in <module>
    main()
  File "c:/Users/g-oft/OneDrive/Dokumenter/DG/dg-prosjekt/pling-project/main.py", line 46, in main
    meny = plingMeny(verbose=VERBOSE)
  File "c:\Users\g-oft\OneDrive\Dokumenter\DG\dg-prosjekt\pling-project\plingMeny.py", line 30, in __init__
    icon = Tkinter.PhotoImage(file=os.path.join(self.script_dir,'files/icon.png'))
  File "C:\Python27\lib\lib-tk\Tkinter.py", line 3366, in __init__
    Image.__init__(self, 'photo', name, cnf, master, **kw)
  File "C:\Python27\lib\lib-tk\Tkinter.py", line 3320, in __init__
    self.tk.call(('image', 'create', imgtype, name,) + options)
TclError: couldn't recognize data in image file "c:\Users\g-oft\OneDrive\Dokumenter\DG\dg-prosjekt\pling-project\files/icon.png"
ERROR:root:
02/20/20 20:59:25
Traceback (most recent call last):
  File "c:/Users/g-oft/OneDrive/Dokumenter/DG/dg-prosjekt/pling-project/main.py", line 66, in <module>
    main()
  File "c:/Users/g-oft/OneDrive/Dokumenter/DG/dg-prosjekt/pling-project/main.py", line 47, in main
    meny = plingMeny(verbose=VERBOSE)
  File "c:\Users\g-oft\OneDrive\Dokumenter\DG\dg-prosjekt\pling-project\plingMeny.py", line 30, in __init__
    icon = Tkinter.PhotoImage(file=os.path.join(self.script_dir,'files/icon.png'))
  File "C:\Python27\lib\lib-tk\Tkinter.py", line 3366, in __init__
    Image.__init__(self, 'photo', name, cnf, master, **kw)
  File "C:\Python27\lib\lib-tk\Tkinter.py", line 3320, in __init__
    self.tk.call(('image', 'create', imgtype, name,) + options)
TclError: couldn't recognize data in image file "c:\Users\g-oft\OneDrive\Dokumenter\DG\dg-prosjekt\pling-project\files/icon.png"
ERROR:root:
02/20/20 20:59:56
Traceback (most recent call last):
  File "c:/Users/g-oft/OneDrive/Dokumenter/DG/dg-prosjekt/pling-project/main.py", line 67, in <module>
    main()
  File "c:/Users/g-oft/OneDrive/Dokumenter/DG/dg-prosjekt/pling-project/main.py", line 47, in main
    meny = plingMeny(verbose=VERBOSE)
  File "c:\Users\g-oft\OneDrive\Dokumenter\DG\dg-prosjekt\pling-project\plingMeny.py", line 30, in __init__
    icon = Tkinter.PhotoImage(file=os.path.join(self.script_dir,'files/icon.png'))
  File "C:\Python27\lib\lib-tk\Tkinter.py", line 3366, in __init__
    Image.__init__(self, 'photo', name, cnf, master, **kw)
  File "C:\Python27\lib\lib-tk\Tkinter.py", line 3320, in __init__
    self.tk.call(('image', 'create', imgtype, name,) + options)
TclError: couldn't recognize data in image file "c:\Users\g-oft\OneDrive\Dokumenter\DG\dg-prosjekt\pling-project\files/icon.png"
ERROR:root:
02/20/20 21:00:09
Traceback (most recent call last):
  File "c:/Users/g-oft/OneDrive/Dokumenter/DG/dg-prosjekt/pling-project/main.py", line 67, in <module>
    main()
  File "c:/Users/g-oft/OneDrive/Dokumenter/DG/dg-prosjekt/pling-project/main.py", line 47, in main
    meny = plingMeny(verbose=VERBOSE)
  File "c:\Users\g-oft\OneDrive\Dokumenter\DG\dg-prosjekt\pling-project\plingMeny.py", line 30, in __init__
    icon = Tkinter.PhotoImage(file=os.path.join(self.script_dir,'files/icon.png'))
  File "C:\Python27\lib\lib-tk\Tkinter.py", line 3366, in __init__
    Image.__init__(self, 'photo', name, cnf, master, **kw)
  File "C:\Python27\lib\lib-tk\Tkinter.py", line 3320, in __init__
    self.tk.call(('image', 'create', imgtype, name,) + options)
TclError: couldn't recognize data in image file "c:\Users\g-oft\OneDrive\Dokumenter\DG\dg-prosjekt\pling-project\files/icon.png"
ERROR:root:
02/20/20 21:01:31
Traceback (most recent call last):
  File "c:/Users/g-oft/OneDrive/Dokumenter/DG/dg-prosjekt/pling-project/main.py", line 67, in <module>
    main()
  File "c:/Users/g-oft/OneDrive/Dokumenter/DG/dg-prosjekt/pling-project/main.py", line 47, in main
    meny = plingMeny(verbose=VERBOSE)
  File "c:\Users\g-oft\OneDrive\Dokumenter\DG\dg-prosjekt\pling-project\plingMeny.py", line 30, in __init__
    icon = Tkinter.PhotoImage(file=os.path.join(self.script_dir,'files/icon.png'))
  File "C:\Python27\lib\lib-tk\Tkinter.py", line 3366, in __init__
    Image.__init__(self, 'photo', name, cnf, master, **kw)
  File "C:\Python27\lib\lib-tk\Tkinter.py", line 3320, in __init__
    self.tk.call(('image', 'create', imgtype, name,) + options)
TclError: couldn't recognize data in image file "c:\Users\g-oft\OneDrive\Dokumenter\DG\dg-prosjekt\pling-project\files/icon.png"
ERROR:root:
02/20/20 21:29:04
Traceback (most recent call last):
  File "c:/Users/g-oft/OneDrive/Dokumenter/DG/dg-prosjekt/pling-project/main.py", line 67, in <module>
    main()
  File "c:/Users/g-oft/OneDrive/Dokumenter/DG/dg-prosjekt/pling-project/main.py", line 47, in main
    meny = plingMeny(verbose=VERBOSE)
  File "c:\Users\g-oft\OneDrive\Dokumenter\DG\dg-prosjekt\pling-project\plingMeny.py", line 30, in __init__
    icon = Tkinter.PhotoImage(file=os.path.join(self.script_dir,'files/icon.png'))
  File "C:\Python27\lib\lib-tk\Tkinter.py", line 3366, in __init__
    Image.__init__(self, 'photo', name, cnf, master, **kw)
  File "C:\Python27\lib\lib-tk\Tkinter.py", line 3320, in __init__
    self.tk.call(('image', 'create', imgtype, name,) + options)
TclError: couldn't recognize data in image file "c:\Users\g-oft\OneDrive\Dokumenter\DG\dg-prosjekt\pling-project\files/icon.png"
ERROR:root:
02/20/20 21:32:38
Traceback (most recent call last):
  File "main.py", line 67, in <module>
    main()
  File "main.py", line 47, in main
    meny = plingMeny(verbose=VERBOSE)
  File "C:\Users\g-oft\OneDrive\Dokumenter\DG\dg-prosjekt\pling-project\plingMeny.py", line 30, in __init__
    icon = Tkinter.PhotoImage(file=os.path.join(self.script_dir,'files/icon.png'))
  File "C:\Python27\lib\lib-tk\Tkinter.py", line 3366, in __init__
    Image.__init__(self, 'photo', name, cnf, master, **kw)
  File "C:\Python27\lib\lib-tk\Tkinter.py", line 3320, in __init__
    self.tk.call(('image', 'create', imgtype, name,) + options)
TclError: couldn't recognize data in image file "C:\Users\g-oft\OneDrive\Dokumenter\DG\dg-prosjekt\pling-project\files/icon.png"
ERROR:root:
02/20/20 21:33:57
Traceback (most recent call last):
  File "main.py", line 67, in <module>
    main()
  File "main.py", line 47, in main
    meny = plingMeny(verbose=VERBOSE)
  File "C:\Users\g-oft\OneDrive\Dokumenter\DG\dg-prosjekt\pling-project\plingMeny.py", line 30, in __init__
    icon = Tkinter.PhotoImage(file=os.path.join(self.script_dir,'files/icon.png'))
  File "C:\Python27\lib\lib-tk\Tkinter.py", line 3366, in __init__
    Image.__init__(self, 'photo', name, cnf, master, **kw)
  File "C:\Python27\lib\lib-tk\Tkinter.py", line 3320, in __init__
    self.tk.call(('image', 'create', imgtype, name,) + options)
TclError: couldn't recognize data in image file "C:\Users\g-oft\OneDrive\Dokumenter\DG\dg-prosjekt\pling-project\files/icon.png"
ERROR:root:
02/20/20 23:13:49
Traceback (most recent call last):
  File "main.py", line 65, in <module>
    main()
  File "main.py", line 49, in main
    meny.run()
  File "C:\Users\g-oft\OneDrive\Dokumenter\DG\dg-prosjekt\pling-project\plingMeny.py", line 212, in run
    self.musicCtrl.startPling()
  File "C:\Users\g-oft\OneDrive\Dokumenter\DG\dg-prosjekt\pling-project\musicControl.py", line 109, in startPling
    self.playSong()
  File "C:\Users\g-oft\OneDrive\Dokumenter\DG\dg-prosjekt\pling-project\musicControl.py", line 26, in playSong
    pling("play")
NameError: global name 'pling' is not defined
ERROR:root:
02/20/20 23:13:56
Traceback (most recent call last):
  File "main.py", line 65, in <module>
    main()
  File "main.py", line 49, in main
    meny.run()
  File "C:\Users\g-oft\OneDrive\Dokumenter\DG\dg-prosjekt\pling-project\plingMeny.py", line 212, in run
    self.musicCtrl.startPling()
  File "C:\Users\g-oft\OneDrive\Dokumenter\DG\dg-prosjekt\pling-project\musicControl.py", line 109, in startPling
    self.playSong()
  File "C:\Users\g-oft\OneDrive\Dokumenter\DG\dg-prosjekt\pling-project\musicControl.py", line 26, in playSong
    pling("play")
NameError: global name 'pling' is not defined
ERROR:root:
02/23/20 18:26:03
Traceback (most recent call last):
  File "c:/Users/g-oft/OneDrive/Dokumenter/DG/dg-prosjekt/pling-project/main.py", line 68, in <module>
    main()
  File "c:/Users/g-oft/OneDrive/Dokumenter/DG/dg-prosjekt/pling-project/main.py", line 55, in main
    print(name)
NameError: global name 'name' is not defined
ERROR:root:
02/23/20 18:26:34
Traceback (most recent call last):
  File "c:/Users/g-oft/OneDrive/Dokumenter/DG/dg-prosjekt/pling-project/main.py", line 68, in <module>
    main()
  File "c:/Users/g-oft/OneDrive/Dokumenter/DG/dg-prosjekt/pling-project/main.py", line 55, in main
    print(name)
NameError: global name 'name' is not defined
ERROR:root:
02/23/20 18:27:51
Traceback (most recent call last):
  File "c:/Users/g-oft/OneDrive/Dokumenter/DG/dg-prosjekt/pling-project/main.py", line 68, in <module>
    main()
  File "c:/Users/g-oft/OneDrive/Dokumenter/DG/dg-prosjekt/pling-project/main.py", line 53, in main
    meny.start()
AttributeError: plingMeny instance has no attribute 'start'
ERROR:root:
02/23/20 21:06:29
Traceback (most recent call last):
  File "c:/Users/g-oft/OneDrive/Dokumenter/DG/dg-prosjekt/pling-project/main.py", line 64, in <module>
    main()
  File "c:/Users/g-oft/OneDrive/Dokumenter/DG/dg-prosjekt/pling-project/main.py", line 49, in main
    meny.run()
  File "c:\Users\g-oft\OneDrive\Dokumenter\DG\dg-prosjekt\pling-project\plingMeny.py", line 221, in run
    master.mainloop()
NameError: global name 'master' is not defined
ERROR:root:
02/23/20 21:24:10
Traceback (most recent call last):
  File "c:/Users/g-oft/OneDrive/Dokumenter/DG/dg-prosjekt/pling-project/main.py", line 66, in <module>
    main()
  File "c:/Users/g-oft/OneDrive/Dokumenter/DG/dg-prosjekt/pling-project/main.py", line 50, in main
    name = meny.run()
  File "c:\Users\g-oft\OneDrive\Dokumenter\DG\dg-prosjekt\pling-project\plingMeny.py", line 226, in run
    return plinger_name
NameError: global name 'plinger_name' is not defined
ERROR:root:
02/23/20 21:29:26
Traceback (most recent call last):
  File "c:/Users/g-oft/OneDrive/Dokumenter/DG/dg-prosjekt/pling-project/main.py", line 66, in <module>
    main()
  File "c:/Users/g-oft/OneDrive/Dokumenter/DG/dg-prosjekt/pling-project/main.py", line 51, in main
    print(meny.get_name())
TypeError: get_name() takes no arguments (1 given)
ERROR:root:
02/23/20 21:29:45
Traceback (most recent call last):
  File "c:/Users/g-oft/OneDrive/Dokumenter/DG/dg-prosjekt/pling-project/main.py", line 66, in <module>
    main()
  File "c:/Users/g-oft/OneDrive/Dokumenter/DG/dg-prosjekt/pling-project/main.py", line 51, in main
    print(meny.get_name())
TypeError: get_name() takes no arguments (1 given)
ERROR:root:
02/23/20 21:30:19
Traceback (most recent call last):
  File "c:/Users/g-oft/OneDrive/Dokumenter/DG/dg-prosjekt/pling-project/main.py", line 66, in <module>
    main()
  File "c:/Users/g-oft/OneDrive/Dokumenter/DG/dg-prosjekt/pling-project/main.py", line 51, in main
    print(meny.get_name())
TypeError: get_name() takes no arguments (1 given)
ERROR:root:
02/23/20 21:31:22
Traceback (most recent call last):
  File "c:/Users/g-oft/OneDrive/Dokumenter/DG/dg-prosjekt/pling-project/main.py", line 66, in <module>
    main()
  File "c:/Users/g-oft/OneDrive/Dokumenter/DG/dg-prosjekt/pling-project/main.py", line 51, in main
    name = meny.get_name()
TypeError: get_name() takes no arguments (1 given)
ERROR:root:
02/23/20 21:33:55
Traceback (most recent call last):
  File "c:/Users/g-oft/OneDrive/Dokumenter/DG/dg-prosjekt/pling-project/main.py", line 66, in <module>
    main()
  File "c:/Users/g-oft/OneDrive/Dokumenter/DG/dg-prosjekt/pling-project/main.py", line 51, in main
    meny.get_name()
TypeError: get_name() takes no arguments (1 given)
